[10/Oct/2025 21:01:31] "GET / HTTP/1.1" 200 44210
[10/Oct/2025 21:01:31] "GET /static/js/theme-manager.js?v=2.8 HTTP/1.1" 304 0
[10/Oct/2025 21:01:31] "GET /static/js/main.js?v=5.0 HTTP/1.1" 304 0
[10/Oct/2025 21:01:31] "GET /static/css/style.css?v=6.4 HTTP/1.1" 200 44392
[10/Oct/2025 21:01:31] "GET /media/backgrounds/Untitled_design_2.png HTTP/1.1" 304 0
[10/Oct/2025 21:01:31] "GET /api/theme/ HTTP/1.1" 200 1262
[10/Oct/2025 21:01:32] "GET /favicon.ico HTTP/1.1" 302 0
[10/Oct/2025 21:01:32] "GET /static/favicon.ico HTTP/1.1" 304 0
[10/Oct/2025 21:01:36] "GET /api/theme/ HTTP/1.1" 200 1262
[10/Oct/2025 21:01:41] "GET /api/theme/ HTTP/1.1" 200 1262
[10/Oct/2025 21:01:46] "GET /api/theme/ HTTP/1.1" 200 1262
[10/Oct/2025 21:01:51] "GET /api/theme/ HTTP/1.1" 200 1262
[10/Oct/2025 21:01:56] "GET /api/theme/ HTTP/1.1" 200 1262
[10/Oct/2025 21:02:01] "GET /api/theme/ HTTP/1.1" 200 1262
[10/Oct/2025 21:02:07] "GET /api/theme/ HTTP/1.1" 200 1262
[10/Oct/2025 21:02:12] "GET /api/theme/ HTTP/1.1" 200 1262
[10/Oct/2025 21:02:17] "GET /api/theme/ HTTP/1.1" 200 1262
[10/Oct/2025 21:02:22] "GET /api/theme/ HTTP/1.1" 200 1262
[10/Oct/2025 21:02:27] "GET /api/theme/ HTTP/1.1" 200 1262
[10/Oct/2025 21:02:32] "GET /api/theme/ HTTP/1.1" 200 1262
[10/Oct/2025 21:02:37] "GET /api/theme/ HTTP/1.1" 200 1262
[10/Oct/2025 21:02:42] "GET /api/theme/ HTTP/1.1" 200 1262
[10/Oct/2025 21:02:47] "GET /api/theme/ HTTP/1.1" 200 1262
[10/Oct/2025 21:02:52] "GET /api/theme/ HTTP/1.1" 200 1262
[10/Oct/2025 21:02:57] "GET /api/theme/ HTTP/1.1" 200 1262
[10/Oct/2025 21:03:02] "GET /api/theme/ HTTP/1.1" 200 1262
[10/Oct/2025 21:04:03] "GET /api/theme/ HTTP/1.1" 200 1262
Internal Server Error: /api/theme/
Internal Server Error: /api/theme/
[10/Oct/2025 21:05:04] "GET /api/theme/ HTTP/1.1" 500 59
Internal Server Error: /api/theme/
Internal Server Error: /api/theme/
[10/Oct/2025 21:06:04] "GET /api/theme/ HTTP/1.1" 500 59
Internal Server Error: /api/theme/
Internal Server Error: /api/theme/
[10/Oct/2025 21:07:04] "GET /api/theme/ HTTP/1.1" 500 59
Internal Server Error: /api/theme/
Internal Server Error: /api/theme/
[10/Oct/2025 21:08:04] "GET /api/theme/ HTTP/1.1" 500 59
Internal Server Error: /api/theme/
Internal Server Error: /api/theme/
[10/Oct/2025 21:09:04] "GET /api/theme/ HTTP/1.1" 500 59
Internal Server Error: /api/theme/
Internal Server Error: /api/theme/
[10/Oct/2025 21:10:04] "GET /api/theme/ HTTP/1.1" 500 59
Internal Server Error: /api/theme/
Internal Server Error: /api/theme/
[10/Oct/2025 21:11:04] "GET /api/theme/ HTTP/1.1" 500 59
Internal Server Error: /api/theme/
Internal Server Error: /api/theme/
[10/Oct/2025 21:12:04] "GET /api/theme/ HTTP/1.1" 500 59
Internal Server Error: /api/theme/
Internal Server Error: /api/theme/
[10/Oct/2025 21:13:04] "GET /api/theme/ HTTP/1.1" 500 59
Internal Server Error: /api/theme/
Internal Server Error: /api/theme/
[10/Oct/2025 21:14:04] "GET /api/theme/ HTTP/1.1" 500 59
Internal Server Error: /api/theme/
Internal Server Error: /api/theme/
[10/Oct/2025 21:15:04] "GET /api/theme/ HTTP/1.1" 500 59
Internal Server Error: /api/theme/
Internal Server Error: /api/theme/
[10/Oct/2025 21:16:04] "GET /api/theme/ HTTP/1.1" 500 59
Internal Server Error: /api/theme/
Internal Server Error: /api/theme/
[10/Oct/2025 21:17:04] "GET /api/theme/ HTTP/1.1" 500 59
Internal Server Error: /api/theme/
Internal Server Error: /api/theme/
[10/Oct/2025 21:18:04] "GET /api/theme/ HTTP/1.1" 500 59
Internal Server Error: /api/theme/
Internal Server Error: /api/theme/
[10/Oct/2025 21:19:04] "GET /api/theme/ HTTP/1.1" 500 59
Internal Server Error: /api/theme/
Internal Server Error: /api/theme/
[10/Oct/2025 21:20:04] "GET /api/theme/ HTTP/1.1" 500 59
Internal Server Error: /api/theme/
Internal Server Error: /api/theme/
[10/Oct/2025 21:21:04] "GET /api/theme/ HTTP/1.1" 500 59
Internal Server Error: /api/theme/
Internal Server Error: /api/theme/
[10/Oct/2025 21:24:22] "GET /api/theme/ HTTP/1.1" 500 59
Internal Server Error: /api/theme/
Internal Server Error: /api/theme/
[10/Oct/2025 21:27:27] "GET /api/theme/ HTTP/1.1" 500 59
Internal Server Error: /api/theme/
Internal Server Error: /api/theme/
[10/Oct/2025 21:30:41] "GET /api/theme/ HTTP/1.1" 500 59
Internal Server Error: /api/theme/
Internal Server Error: /api/theme/
[10/Oct/2025 21:47:01] "GET /api/theme/ HTTP/1.1" 500 59
Internal Server Error: /api/theme/
Internal Server Error: /api/theme/
[10/Oct/2025 21:48:01] "GET /api/theme/ HTTP/1.1" 500 59
Internal Server Error: /api/theme/
Internal Server Error: /api/theme/
[10/Oct/2025 21:49:01] "GET /api/theme/ HTTP/1.1" 500 59
Internal Server Error: /api/theme/
Internal Server Error: /api/theme/
[10/Oct/2025 21:50:01] "GET /api/theme/ HTTP/1.1" 500 59
Internal Server Error: /api/theme/
Internal Server Error: /api/theme/
[10/Oct/2025 21:51:01] "GET /api/theme/ HTTP/1.1" 500 59
Internal Server Error: /api/theme/
Internal Server Error: /api/theme/
[10/Oct/2025 21:52:01] "GET /api/theme/ HTTP/1.1" 500 59
Internal Server Error: /api/theme/
Internal Server Error: /api/theme/
[10/Oct/2025 21:53:01] "GET /api/theme/ HTTP/1.1" 500 59
Internal Server Error: /api/theme/
Internal Server Error: /api/theme/
[10/Oct/2025 21:54:01] "GET /api/theme/ HTTP/1.1" 500 59
Internal Server Error: /api/theme/
Internal Server Error: /api/theme/
[10/Oct/2025 21:55:01] "GET /api/theme/ HTTP/1.1" 500 59
Internal Server Error: /api/theme/
Internal Server Error: /api/theme/
[10/Oct/2025 21:56:01] "GET /api/theme/ HTTP/1.1" 500 59
Internal Server Error: /api/theme/
Internal Server Error: /api/theme/
[10/Oct/2025 21:57:01] "GET /api/theme/ HTTP/1.1" 500 59
Internal Server Error: /api/theme/
Internal Server Error: /api/theme/
[10/Oct/2025 21:58:01] "GET /api/theme/ HTTP/1.1" 500 59
Internal Server Error: /api/theme/
Internal Server Error: /api/theme/
[10/Oct/2025 21:59:01] "GET /api/theme/ HTTP/1.1" 500 59
Internal Server Error: /api/theme/
Internal Server Error: /api/theme/
[10/Oct/2025 22:00:01] "GET /api/theme/ HTTP/1.1" 500 59
Internal Server Error: /api/theme/
Internal Server Error: /api/theme/
[10/Oct/2025 22:17:14] "GET /api/theme/ HTTP/1.1" 500 59
Internal Server Error: /api/theme/
Internal Server Error: /api/theme/
[10/Oct/2025 22:18:14] "GET /api/theme/ HTTP/1.1" 500 59
Internal Server Error: /api/theme/
Internal Server Error: /api/theme/
[10/Oct/2025 22:26:27] "GET /api/theme/ HTTP/1.1" 500 59
Internal Server Error: /api/theme/
Internal Server Error: /api/theme/
[10/Oct/2025 22:27:27] "GET /api/theme/ HTTP/1.1" 500 59
Internal Server Error: /api/theme/
Internal Server Error: /api/theme/
[10/Oct/2025 22:28:27] "GET /api/theme/ HTTP/1.1" 500 59
Internal Server Error: /api/theme/
Internal Server Error: /api/theme/
[10/Oct/2025 22:30:23] "GET /api/theme/ HTTP/1.1" 500 59
Internal Server Error: /api/theme/
Internal Server Error: /api/theme/
[10/Oct/2025 22:31:23] "GET /api/theme/ HTTP/1.1" 500 59
Internal Server Error: /api/theme/
Internal Server Error: /api/theme/
[10/Oct/2025 22:32:23] "GET /api/theme/ HTTP/1.1" 500 59
Internal Server Error: /api/theme/
Internal Server Error: /api/theme/
[10/Oct/2025 22:33:23] "GET /api/theme/ HTTP/1.1" 500 59
Internal Server Error: /api/theme/
Internal Server Error: /api/theme/
[10/Oct/2025 22:47:29] "GET /api/theme/ HTTP/1.1" 500 59
Internal Server Error: /api/theme/
Internal Server Error: /api/theme/
[10/Oct/2025 22:50:29] "GET /api/theme/ HTTP/1.1" 500 59
Internal Server Error: /api/theme/
Internal Server Error: /api/theme/
[10/Oct/2025 22:59:14] "GET /api/theme/ HTTP/1.1" 500 59
Internal Server Error: /api/theme/
Internal Server Error: /api/theme/
[10/Oct/2025 23:00:14] "GET /api/theme/ HTTP/1.1" 500 59
Internal Server Error: /api/theme/
Internal Server Error: /api/theme/
[10/Oct/2025 23:00:26] "GET /api/theme/ HTTP/1.1" 500 59
Internal Server Error: /api/theme/
Internal Server Error: /api/theme/
[10/Oct/2025 23:00:26] "GET /api/theme/ HTTP/1.1" 500 59
Internal Server Error: /
Traceback (most recent call last):
  File "/Users/shazibsiddique/solo-projects/Personal_Portfolio-2.0-/venv/lib/python3.11/site-packages/django/db/backends/utils.py", line 105, in _execute
    return self.cursor.execute(sql, params)
           ^^^^^^^^^^^^^^^^^^^^^^^^^^^^^^^^
  File "/Users/shazibsiddique/solo-projects/Personal_Portfolio-2.0-/venv/lib/python3.11/site-packages/django/db/backends/sqlite3/base.py", line 360, in execute
    return super().execute(query, params)
           ^^^^^^^^^^^^^^^^^^^^^^^^^^^^^^
sqlite3.OperationalError: no such column: app_sitesettings.pinterest_url

The above exception was the direct cause of the following exception:

Traceback (most recent call last):
  File "/Users/shazibsiddique/solo-projects/Personal_Portfolio-2.0-/venv/lib/python3.11/site-packages/django/core/handlers/exception.py", line 55, in inner
    response = get_response(request)
               ^^^^^^^^^^^^^^^^^^^^^
  File "/Users/shazibsiddique/solo-projects/Personal_Portfolio-2.0-/venv/lib/python3.11/site-packages/django/core/handlers/base.py", line 197, in _get_response
    response = wrapped_callback(request, *callback_args, **callback_kwargs)
               ^^^^^^^^^^^^^^^^^^^^^^^^^^^^^^^^^^^^^^^^^^^^^^^^^^^^^^^^^^^^
  File "/Users/shazibsiddique/solo-projects/Personal_Portfolio-2.0-/app/views.py", line 115, in home_view
    site_settings = SiteSettings.objects.first()
                    ^^^^^^^^^^^^^^^^^^^^^^^^^^^^
  File "/Users/shazibsiddique/solo-projects/Personal_Portfolio-2.0-/venv/lib/python3.11/site-packages/django/db/models/manager.py", line 87, in manager_method
    return getattr(self.get_queryset(), name)(*args, **kwargs)
           ^^^^^^^^^^^^^^^^^^^^^^^^^^^^^^^^^^^^^^^^^^^^^^^^^^^
  File "/Users/shazibsiddique/solo-projects/Personal_Portfolio-2.0-/venv/lib/python3.11/site-packages/django/db/models/query.py", line 1104, in first
    for obj in queryset[:1]:
  File "/Users/shazibsiddique/solo-projects/Personal_Portfolio-2.0-/venv/lib/python3.11/site-packages/django/db/models/query.py", line 384, in __iter__
    self._fetch_all()
  File "/Users/shazibsiddique/solo-projects/Personal_Portfolio-2.0-/venv/lib/python3.11/site-packages/django/db/models/query.py", line 1949, in _fetch_all
    self._result_cache = list(self._iterable_class(self))
                         ^^^^^^^^^^^^^^^^^^^^^^^^^^^^^^^^
  File "/Users/shazibsiddique/solo-projects/Personal_Portfolio-2.0-/venv/lib/python3.11/site-packages/django/db/models/query.py", line 91, in __iter__
    results = compiler.execute_sql(
              ^^^^^^^^^^^^^^^^^^^^^
  File "/Users/shazibsiddique/solo-projects/Personal_Portfolio-2.0-/venv/lib/python3.11/site-packages/django/db/models/sql/compiler.py", line 1623, in execute_sql
    cursor.execute(sql, params)
  File "/Users/shazibsiddique/solo-projects/Personal_Portfolio-2.0-/venv/lib/python3.11/site-packages/django/db/backends/utils.py", line 122, in execute
    return super().execute(sql, params)
           ^^^^^^^^^^^^^^^^^^^^^^^^^^^^
  File "/Users/shazibsiddique/solo-projects/Personal_Portfolio-2.0-/venv/lib/python3.11/site-packages/django/db/backends/utils.py", line 79, in execute
    return self._execute_with_wrappers(
           ^^^^^^^^^^^^^^^^^^^^^^^^^^^^
  File "/Users/shazibsiddique/solo-projects/Personal_Portfolio-2.0-/venv/lib/python3.11/site-packages/django/db/backends/utils.py", line 92, in _execute_with_wrappers
    return executor(sql, params, many, context)
           ^^^^^^^^^^^^^^^^^^^^^^^^^^^^^^^^^^^^
  File "/Users/shazibsiddique/solo-projects/Personal_Portfolio-2.0-/venv/lib/python3.11/site-packages/django/db/backends/utils.py", line 100, in _execute
    with self.db.wrap_database_errors:
  File "/Users/shazibsiddique/solo-projects/Personal_Portfolio-2.0-/venv/lib/python3.11/site-packages/django/db/utils.py", line 91, in __exit__
    raise dj_exc_value.with_traceback(traceback) from exc_value
  File "/Users/shazibsiddique/solo-projects/Personal_Portfolio-2.0-/venv/lib/python3.11/site-packages/django/db/backends/utils.py", line 105, in _execute
    return self.cursor.execute(sql, params)
           ^^^^^^^^^^^^^^^^^^^^^^^^^^^^^^^^
  File "/Users/shazibsiddique/solo-projects/Personal_Portfolio-2.0-/venv/lib/python3.11/site-packages/django/db/backends/sqlite3/base.py", line 360, in execute
    return super().execute(query, params)
           ^^^^^^^^^^^^^^^^^^^^^^^^^^^^^^
django.db.utils.OperationalError: no such column: app_sitesettings.pinterest_url
Internal Server Error: /
Traceback (most recent call last):
  File "/Users/shazibsiddique/solo-projects/Personal_Portfolio-2.0-/venv/lib/python3.11/site-packages/django/db/backends/utils.py", line 105, in _execute
    return self.cursor.execute(sql, params)
           ^^^^^^^^^^^^^^^^^^^^^^^^^^^^^^^^
  File "/Users/shazibsiddique/solo-projects/Personal_Portfolio-2.0-/venv/lib/python3.11/site-packages/django/db/backends/sqlite3/base.py", line 360, in execute
    return super().execute(query, params)
           ^^^^^^^^^^^^^^^^^^^^^^^^^^^^^^
sqlite3.OperationalError: no such column: app_sitesettings.pinterest_url

The above exception was the direct cause of the following exception:

Traceback (most recent call last):
  File "/Users/shazibsiddique/solo-projects/Personal_Portfolio-2.0-/venv/lib/python3.11/site-packages/django/core/handlers/exception.py", line 55, in inner
    response = get_response(request)
               ^^^^^^^^^^^^^^^^^^^^^
  File "/Users/shazibsiddique/solo-projects/Personal_Portfolio-2.0-/venv/lib/python3.11/site-packages/django/core/handlers/base.py", line 197, in _get_response
    response = wrapped_callback(request, *callback_args, **callback_kwargs)
               ^^^^^^^^^^^^^^^^^^^^^^^^^^^^^^^^^^^^^^^^^^^^^^^^^^^^^^^^^^^^
  File "/Users/shazibsiddique/solo-projects/Personal_Portfolio-2.0-/app/views.py", line 115, in home_view
    site_settings = SiteSettings.objects.first()
                    ^^^^^^^^^^^^^^^^^^^^^^^^^^^^
  File "/Users/shazibsiddique/solo-projects/Personal_Portfolio-2.0-/venv/lib/python3.11/site-packages/django/db/models/manager.py", line 87, in manager_method
    return getattr(self.get_queryset(), name)(*args, **kwargs)
           ^^^^^^^^^^^^^^^^^^^^^^^^^^^^^^^^^^^^^^^^^^^^^^^^^^^
  File "/Users/shazibsiddique/solo-projects/Personal_Portfolio-2.0-/venv/lib/python3.11/site-packages/django/db/models/query.py", line 1104, in first
    for obj in queryset[:1]:
  File "/Users/shazibsiddique/solo-projects/Personal_Portfolio-2.0-/venv/lib/python3.11/site-packages/django/db/models/query.py", line 384, in __iter__
    self._fetch_all()
  File "/Users/shazibsiddique/solo-projects/Personal_Portfolio-2.0-/venv/lib/python3.11/site-packages/django/db/models/query.py", line 1949, in _fetch_all
    self._result_cache = list(self._iterable_class(self))
                         ^^^^^^^^^^^^^^^^^^^^^^^^^^^^^^^^
  File "/Users/shazibsiddique/solo-projects/Personal_Portfolio-2.0-/venv/lib/python3.11/site-packages/django/db/models/query.py", line 91, in __iter__
    results = compiler.execute_sql(
              ^^^^^^^^^^^^^^^^^^^^^
  File "/Users/shazibsiddique/solo-projects/Personal_Portfolio-2.0-/venv/lib/python3.11/site-packages/django/db/models/sql/compiler.py", line 1623, in execute_sql
    cursor.execute(sql, params)
  File "/Users/shazibsiddique/solo-projects/Personal_Portfolio-2.0-/venv/lib/python3.11/site-packages/django/db/backends/utils.py", line 122, in execute
    return super().execute(sql, params)
           ^^^^^^^^^^^^^^^^^^^^^^^^^^^^
  File "/Users/shazibsiddique/solo-projects/Personal_Portfolio-2.0-/venv/lib/python3.11/site-packages/django/db/backends/utils.py", line 79, in execute
    return self._execute_with_wrappers(
           ^^^^^^^^^^^^^^^^^^^^^^^^^^^^
  File "/Users/shazibsiddique/solo-projects/Personal_Portfolio-2.0-/venv/lib/python3.11/site-packages/django/db/backends/utils.py", line 92, in _execute_with_wrappers
    return executor(sql, params, many, context)
           ^^^^^^^^^^^^^^^^^^^^^^^^^^^^^^^^^^^^
  File "/Users/shazibsiddique/solo-projects/Personal_Portfolio-2.0-/venv/lib/python3.11/site-packages/django/db/backends/utils.py", line 100, in _execute
    with self.db.wrap_database_errors:
  File "/Users/shazibsiddique/solo-projects/Personal_Portfolio-2.0-/venv/lib/python3.11/site-packages/django/db/utils.py", line 91, in __exit__
    raise dj_exc_value.with_traceback(traceback) from exc_value
  File "/Users/shazibsiddique/solo-projects/Personal_Portfolio-2.0-/venv/lib/python3.11/site-packages/django/db/backends/utils.py", line 105, in _execute
    return self.cursor.execute(sql, params)
           ^^^^^^^^^^^^^^^^^^^^^^^^^^^^^^^^
  File "/Users/shazibsiddique/solo-projects/Personal_Portfolio-2.0-/venv/lib/python3.11/site-packages/django/db/backends/sqlite3/base.py", line 360, in execute
    return super().execute(query, params)
           ^^^^^^^^^^^^^^^^^^^^^^^^^^^^^^
django.db.utils.OperationalError: no such column: app_sitesettings.pinterest_url
[10/Oct/2025 23:00:29] "GET / HTTP/1.1" 500 164668
[10/Oct/2025 23:00:29] "GET /favicon.ico HTTP/1.1" 302 0
Internal Server Error: /
Traceback (most recent call last):
  File "/Users/shazibsiddique/solo-projects/Personal_Portfolio-2.0-/venv/lib/python3.11/site-packages/django/db/backends/utils.py", line 105, in _execute
    return self.cursor.execute(sql, params)
           ^^^^^^^^^^^^^^^^^^^^^^^^^^^^^^^^
  File "/Users/shazibsiddique/solo-projects/Personal_Portfolio-2.0-/venv/lib/python3.11/site-packages/django/db/backends/sqlite3/base.py", line 360, in execute
    return super().execute(query, params)
           ^^^^^^^^^^^^^^^^^^^^^^^^^^^^^^
sqlite3.OperationalError: no such column: app_sitesettings.pinterest_url

The above exception was the direct cause of the following exception:

Traceback (most recent call last):
  File "/Users/shazibsiddique/solo-projects/Personal_Portfolio-2.0-/venv/lib/python3.11/site-packages/django/core/handlers/exception.py", line 55, in inner
    response = get_response(request)
               ^^^^^^^^^^^^^^^^^^^^^
  File "/Users/shazibsiddique/solo-projects/Personal_Portfolio-2.0-/venv/lib/python3.11/site-packages/django/core/handlers/base.py", line 197, in _get_response
    response = wrapped_callback(request, *callback_args, **callback_kwargs)
               ^^^^^^^^^^^^^^^^^^^^^^^^^^^^^^^^^^^^^^^^^^^^^^^^^^^^^^^^^^^^
  File "/Users/shazibsiddique/solo-projects/Personal_Portfolio-2.0-/app/views.py", line 115, in home_view
    site_settings = SiteSettings.objects.first()
                    ^^^^^^^^^^^^^^^^^^^^^^^^^^^^
  File "/Users/shazibsiddique/solo-projects/Personal_Portfolio-2.0-/venv/lib/python3.11/site-packages/django/db/models/manager.py", line 87, in manager_method
    return getattr(self.get_queryset(), name)(*args, **kwargs)
           ^^^^^^^^^^^^^^^^^^^^^^^^^^^^^^^^^^^^^^^^^^^^^^^^^^^
  File "/Users/shazibsiddique/solo-projects/Personal_Portfolio-2.0-/venv/lib/python3.11/site-packages/django/db/models/query.py", line 1104, in first
    for obj in queryset[:1]:
  File "/Users/shazibsiddique/solo-projects/Personal_Portfolio-2.0-/venv/lib/python3.11/site-packages/django/db/models/query.py", line 384, in __iter__
    self._fetch_all()
  File "/Users/shazibsiddique/solo-projects/Personal_Portfolio-2.0-/venv/lib/python3.11/site-packages/django/db/models/query.py", line 1949, in _fetch_all
    self._result_cache = list(self._iterable_class(self))
                         ^^^^^^^^^^^^^^^^^^^^^^^^^^^^^^^^
  File "/Users/shazibsiddique/solo-projects/Personal_Portfolio-2.0-/venv/lib/python3.11/site-packages/django/db/models/query.py", line 91, in __iter__
    results = compiler.execute_sql(
              ^^^^^^^^^^^^^^^^^^^^^
  File "/Users/shazibsiddique/solo-projects/Personal_Portfolio-2.0-/venv/lib/python3.11/site-packages/django/db/models/sql/compiler.py", line 1623, in execute_sql
    cursor.execute(sql, params)
  File "/Users/shazibsiddique/solo-projects/Personal_Portfolio-2.0-/venv/lib/python3.11/site-packages/django/db/backends/utils.py", line 122, in execute
    return super().execute(sql, params)
           ^^^^^^^^^^^^^^^^^^^^^^^^^^^^
  File "/Users/shazibsiddique/solo-projects/Personal_Portfolio-2.0-/venv/lib/python3.11/site-packages/django/db/backends/utils.py", line 79, in execute
    return self._execute_with_wrappers(
           ^^^^^^^^^^^^^^^^^^^^^^^^^^^^
  File "/Users/shazibsiddique/solo-projects/Personal_Portfolio-2.0-/venv/lib/python3.11/site-packages/django/db/backends/utils.py", line 92, in _execute_with_wrappers
    return executor(sql, params, many, context)
           ^^^^^^^^^^^^^^^^^^^^^^^^^^^^^^^^^^^^
  File "/Users/shazibsiddique/solo-projects/Personal_Portfolio-2.0-/venv/lib/python3.11/site-packages/django/db/backends/utils.py", line 100, in _execute
    with self.db.wrap_database_errors:
  File "/Users/shazibsiddique/solo-projects/Personal_Portfolio-2.0-/venv/lib/python3.11/site-packages/django/db/utils.py", line 91, in __exit__
    raise dj_exc_value.with_traceback(traceback) from exc_value
  File "/Users/shazibsiddique/solo-projects/Personal_Portfolio-2.0-/venv/lib/python3.11/site-packages/django/db/backends/utils.py", line 105, in _execute
    return self.cursor.execute(sql, params)
           ^^^^^^^^^^^^^^^^^^^^^^^^^^^^^^^^
  File "/Users/shazibsiddique/solo-projects/Personal_Portfolio-2.0-/venv/lib/python3.11/site-packages/django/db/backends/sqlite3/base.py", line 360, in execute
    return super().execute(query, params)
           ^^^^^^^^^^^^^^^^^^^^^^^^^^^^^^
django.db.utils.OperationalError: no such column: app_sitesettings.pinterest_url
Internal Server Error: /
Traceback (most recent call last):
  File "/Users/shazibsiddique/solo-projects/Personal_Portfolio-2.0-/venv/lib/python3.11/site-packages/django/db/backends/utils.py", line 105, in _execute
    return self.cursor.execute(sql, params)
           ^^^^^^^^^^^^^^^^^^^^^^^^^^^^^^^^
  File "/Users/shazibsiddique/solo-projects/Personal_Portfolio-2.0-/venv/lib/python3.11/site-packages/django/db/backends/sqlite3/base.py", line 360, in execute
    return super().execute(query, params)
           ^^^^^^^^^^^^^^^^^^^^^^^^^^^^^^
sqlite3.OperationalError: no such column: app_sitesettings.pinterest_url

The above exception was the direct cause of the following exception:

Traceback (most recent call last):
  File "/Users/shazibsiddique/solo-projects/Personal_Portfolio-2.0-/venv/lib/python3.11/site-packages/django/core/handlers/exception.py", line 55, in inner
    response = get_response(request)
               ^^^^^^^^^^^^^^^^^^^^^
  File "/Users/shazibsiddique/solo-projects/Personal_Portfolio-2.0-/venv/lib/python3.11/site-packages/django/core/handlers/base.py", line 197, in _get_response
    response = wrapped_callback(request, *callback_args, **callback_kwargs)
               ^^^^^^^^^^^^^^^^^^^^^^^^^^^^^^^^^^^^^^^^^^^^^^^^^^^^^^^^^^^^
  File "/Users/shazibsiddique/solo-projects/Personal_Portfolio-2.0-/app/views.py", line 115, in home_view
    site_settings = SiteSettings.objects.first()
                    ^^^^^^^^^^^^^^^^^^^^^^^^^^^^
  File "/Users/shazibsiddique/solo-projects/Personal_Portfolio-2.0-/venv/lib/python3.11/site-packages/django/db/models/manager.py", line 87, in manager_method
    return getattr(self.get_queryset(), name)(*args, **kwargs)
           ^^^^^^^^^^^^^^^^^^^^^^^^^^^^^^^^^^^^^^^^^^^^^^^^^^^
  File "/Users/shazibsiddique/solo-projects/Personal_Portfolio-2.0-/venv/lib/python3.11/site-packages/django/db/models/query.py", line 1104, in first
    for obj in queryset[:1]:
  File "/Users/shazibsiddique/solo-projects/Personal_Portfolio-2.0-/venv/lib/python3.11/site-packages/django/db/models/query.py", line 384, in __iter__
    self._fetch_all()
  File "/Users/shazibsiddique/solo-projects/Personal_Portfolio-2.0-/venv/lib/python3.11/site-packages/django/db/models/query.py", line 1949, in _fetch_all
    self._result_cache = list(self._iterable_class(self))
                         ^^^^^^^^^^^^^^^^^^^^^^^^^^^^^^^^
  File "/Users/shazibsiddique/solo-projects/Personal_Portfolio-2.0-/venv/lib/python3.11/site-packages/django/db/models/query.py", line 91, in __iter__
    results = compiler.execute_sql(
              ^^^^^^^^^^^^^^^^^^^^^
  File "/Users/shazibsiddique/solo-projects/Personal_Portfolio-2.0-/venv/lib/python3.11/site-packages/django/db/models/sql/compiler.py", line 1623, in execute_sql
    cursor.execute(sql, params)
  File "/Users/shazibsiddique/solo-projects/Personal_Portfolio-2.0-/venv/lib/python3.11/site-packages/django/db/backends/utils.py", line 122, in execute
    return super().execute(sql, params)
           ^^^^^^^^^^^^^^^^^^^^^^^^^^^^
  File "/Users/shazibsiddique/solo-projects/Personal_Portfolio-2.0-/venv/lib/python3.11/site-packages/django/db/backends/utils.py", line 79, in execute
    return self._execute_with_wrappers(
           ^^^^^^^^^^^^^^^^^^^^^^^^^^^^
  File "/Users/shazibsiddique/solo-projects/Personal_Portfolio-2.0-/venv/lib/python3.11/site-packages/django/db/backends/utils.py", line 92, in _execute_with_wrappers
    return executor(sql, params, many, context)
           ^^^^^^^^^^^^^^^^^^^^^^^^^^^^^^^^^^^^
  File "/Users/shazibsiddique/solo-projects/Personal_Portfolio-2.0-/venv/lib/python3.11/site-packages/django/db/backends/utils.py", line 100, in _execute
    with self.db.wrap_database_errors:
  File "/Users/shazibsiddique/solo-projects/Personal_Portfolio-2.0-/venv/lib/python3.11/site-packages/django/db/utils.py", line 91, in __exit__
    raise dj_exc_value.with_traceback(traceback) from exc_value
  File "/Users/shazibsiddique/solo-projects/Personal_Portfolio-2.0-/venv/lib/python3.11/site-packages/django/db/backends/utils.py", line 105, in _execute
    return self.cursor.execute(sql, params)
           ^^^^^^^^^^^^^^^^^^^^^^^^^^^^^^^^
  File "/Users/shazibsiddique/solo-projects/Personal_Portfolio-2.0-/venv/lib/python3.11/site-packages/django/db/backends/sqlite3/base.py", line 360, in execute
    return super().execute(query, params)
           ^^^^^^^^^^^^^^^^^^^^^^^^^^^^^^
django.db.utils.OperationalError: no such column: app_sitesettings.pinterest_url
[10/Oct/2025 23:10:30] "GET / HTTP/1.1" 500 164668
[10/Oct/2025 23:10:30] "GET /favicon.ico HTTP/1.1" 302 0
Internal Server Error: /
Traceback (most recent call last):
  File "/Users/shazibsiddique/solo-projects/Personal_Portfolio-2.0-/venv/lib/python3.11/site-packages/django/db/backends/utils.py", line 105, in _execute
    return self.cursor.execute(sql, params)
           ^^^^^^^^^^^^^^^^^^^^^^^^^^^^^^^^
  File "/Users/shazibsiddique/solo-projects/Personal_Portfolio-2.0-/venv/lib/python3.11/site-packages/django/db/backends/sqlite3/base.py", line 360, in execute
    return super().execute(query, params)
           ^^^^^^^^^^^^^^^^^^^^^^^^^^^^^^
sqlite3.OperationalError: no such column: app_sitesettings.pinterest_url

The above exception was the direct cause of the following exception:

Traceback (most recent call last):
  File "/Users/shazibsiddique/solo-projects/Personal_Portfolio-2.0-/venv/lib/python3.11/site-packages/django/core/handlers/exception.py", line 55, in inner
    response = get_response(request)
               ^^^^^^^^^^^^^^^^^^^^^
  File "/Users/shazibsiddique/solo-projects/Personal_Portfolio-2.0-/venv/lib/python3.11/site-packages/django/core/handlers/base.py", line 197, in _get_response
    response = wrapped_callback(request, *callback_args, **callback_kwargs)
               ^^^^^^^^^^^^^^^^^^^^^^^^^^^^^^^^^^^^^^^^^^^^^^^^^^^^^^^^^^^^
  File "/Users/shazibsiddique/solo-projects/Personal_Portfolio-2.0-/app/views.py", line 115, in home_view
    site_settings = SiteSettings.objects.first()
                    ^^^^^^^^^^^^^^^^^^^^^^^^^^^^
  File "/Users/shazibsiddique/solo-projects/Personal_Portfolio-2.0-/venv/lib/python3.11/site-packages/django/db/models/manager.py", line 87, in manager_method
    return getattr(self.get_queryset(), name)(*args, **kwargs)
           ^^^^^^^^^^^^^^^^^^^^^^^^^^^^^^^^^^^^^^^^^^^^^^^^^^^
  File "/Users/shazibsiddique/solo-projects/Personal_Portfolio-2.0-/venv/lib/python3.11/site-packages/django/db/models/query.py", line 1104, in first
    for obj in queryset[:1]:
  File "/Users/shazibsiddique/solo-projects/Personal_Portfolio-2.0-/venv/lib/python3.11/site-packages/django/db/models/query.py", line 384, in __iter__
    self._fetch_all()
  File "/Users/shazibsiddique/solo-projects/Personal_Portfolio-2.0-/venv/lib/python3.11/site-packages/django/db/models/query.py", line 1949, in _fetch_all
    self._result_cache = list(self._iterable_class(self))
                         ^^^^^^^^^^^^^^^^^^^^^^^^^^^^^^^^
  File "/Users/shazibsiddique/solo-projects/Personal_Portfolio-2.0-/venv/lib/python3.11/site-packages/django/db/models/query.py", line 91, in __iter__
    results = compiler.execute_sql(
              ^^^^^^^^^^^^^^^^^^^^^
  File "/Users/shazibsiddique/solo-projects/Personal_Portfolio-2.0-/venv/lib/python3.11/site-packages/django/db/models/sql/compiler.py", line 1623, in execute_sql
    cursor.execute(sql, params)
  File "/Users/shazibsiddique/solo-projects/Personal_Portfolio-2.0-/venv/lib/python3.11/site-packages/django/db/backends/utils.py", line 122, in execute
    return super().execute(sql, params)
           ^^^^^^^^^^^^^^^^^^^^^^^^^^^^
  File "/Users/shazibsiddique/solo-projects/Personal_Portfolio-2.0-/venv/lib/python3.11/site-packages/django/db/backends/utils.py", line 79, in execute
    return self._execute_with_wrappers(
           ^^^^^^^^^^^^^^^^^^^^^^^^^^^^
  File "/Users/shazibsiddique/solo-projects/Personal_Portfolio-2.0-/venv/lib/python3.11/site-packages/django/db/backends/utils.py", line 92, in _execute_with_wrappers
    return executor(sql, params, many, context)
           ^^^^^^^^^^^^^^^^^^^^^^^^^^^^^^^^^^^^
  File "/Users/shazibsiddique/solo-projects/Personal_Portfolio-2.0-/venv/lib/python3.11/site-packages/django/db/backends/utils.py", line 100, in _execute
    with self.db.wrap_database_errors:
  File "/Users/shazibsiddique/solo-projects/Personal_Portfolio-2.0-/venv/lib/python3.11/site-packages/django/db/utils.py", line 91, in __exit__
    raise dj_exc_value.with_traceback(traceback) from exc_value
  File "/Users/shazibsiddique/solo-projects/Personal_Portfolio-2.0-/venv/lib/python3.11/site-packages/django/db/backends/utils.py", line 105, in _execute
    return self.cursor.execute(sql, params)
           ^^^^^^^^^^^^^^^^^^^^^^^^^^^^^^^^
  File "/Users/shazibsiddique/solo-projects/Personal_Portfolio-2.0-/venv/lib/python3.11/site-packages/django/db/backends/sqlite3/base.py", line 360, in execute
    return super().execute(query, params)
           ^^^^^^^^^^^^^^^^^^^^^^^^^^^^^^
django.db.utils.OperationalError: no such column: app_sitesettings.pinterest_url
Internal Server Error: /
Traceback (most recent call last):
  File "/Users/shazibsiddique/solo-projects/Personal_Portfolio-2.0-/venv/lib/python3.11/site-packages/django/db/backends/utils.py", line 105, in _execute
    return self.cursor.execute(sql, params)
           ^^^^^^^^^^^^^^^^^^^^^^^^^^^^^^^^
  File "/Users/shazibsiddique/solo-projects/Personal_Portfolio-2.0-/venv/lib/python3.11/site-packages/django/db/backends/sqlite3/base.py", line 360, in execute
    return super().execute(query, params)
           ^^^^^^^^^^^^^^^^^^^^^^^^^^^^^^
sqlite3.OperationalError: no such column: app_sitesettings.pinterest_url

The above exception was the direct cause of the following exception:

Traceback (most recent call last):
  File "/Users/shazibsiddique/solo-projects/Personal_Portfolio-2.0-/venv/lib/python3.11/site-packages/django/core/handlers/exception.py", line 55, in inner
    response = get_response(request)
               ^^^^^^^^^^^^^^^^^^^^^
  File "/Users/shazibsiddique/solo-projects/Personal_Portfolio-2.0-/venv/lib/python3.11/site-packages/django/core/handlers/base.py", line 197, in _get_response
    response = wrapped_callback(request, *callback_args, **callback_kwargs)
               ^^^^^^^^^^^^^^^^^^^^^^^^^^^^^^^^^^^^^^^^^^^^^^^^^^^^^^^^^^^^
  File "/Users/shazibsiddique/solo-projects/Personal_Portfolio-2.0-/app/views.py", line 115, in home_view
    site_settings = SiteSettings.objects.first()
                    ^^^^^^^^^^^^^^^^^^^^^^^^^^^^
  File "/Users/shazibsiddique/solo-projects/Personal_Portfolio-2.0-/venv/lib/python3.11/site-packages/django/db/models/manager.py", line 87, in manager_method
    return getattr(self.get_queryset(), name)(*args, **kwargs)
           ^^^^^^^^^^^^^^^^^^^^^^^^^^^^^^^^^^^^^^^^^^^^^^^^^^^
  File "/Users/shazibsiddique/solo-projects/Personal_Portfolio-2.0-/venv/lib/python3.11/site-packages/django/db/models/query.py", line 1104, in first
    for obj in queryset[:1]:
  File "/Users/shazibsiddique/solo-projects/Personal_Portfolio-2.0-/venv/lib/python3.11/site-packages/django/db/models/query.py", line 384, in __iter__
    self._fetch_all()
  File "/Users/shazibsiddique/solo-projects/Personal_Portfolio-2.0-/venv/lib/python3.11/site-packages/django/db/models/query.py", line 1949, in _fetch_all
    self._result_cache = list(self._iterable_class(self))
                         ^^^^^^^^^^^^^^^^^^^^^^^^^^^^^^^^
  File "/Users/shazibsiddique/solo-projects/Personal_Portfolio-2.0-/venv/lib/python3.11/site-packages/django/db/models/query.py", line 91, in __iter__
    results = compiler.execute_sql(
              ^^^^^^^^^^^^^^^^^^^^^
  File "/Users/shazibsiddique/solo-projects/Personal_Portfolio-2.0-/venv/lib/python3.11/site-packages/django/db/models/sql/compiler.py", line 1623, in execute_sql
    cursor.execute(sql, params)
  File "/Users/shazibsiddique/solo-projects/Personal_Portfolio-2.0-/venv/lib/python3.11/site-packages/django/db/backends/utils.py", line 122, in execute
    return super().execute(sql, params)
           ^^^^^^^^^^^^^^^^^^^^^^^^^^^^
  File "/Users/shazibsiddique/solo-projects/Personal_Portfolio-2.0-/venv/lib/python3.11/site-packages/django/db/backends/utils.py", line 79, in execute
    return self._execute_with_wrappers(
           ^^^^^^^^^^^^^^^^^^^^^^^^^^^^
  File "/Users/shazibsiddique/solo-projects/Personal_Portfolio-2.0-/venv/lib/python3.11/site-packages/django/db/backends/utils.py", line 92, in _execute_with_wrappers
    return executor(sql, params, many, context)
           ^^^^^^^^^^^^^^^^^^^^^^^^^^^^^^^^^^^^
  File "/Users/shazibsiddique/solo-projects/Personal_Portfolio-2.0-/venv/lib/python3.11/site-packages/django/db/backends/utils.py", line 100, in _execute
    with self.db.wrap_database_errors:
  File "/Users/shazibsiddique/solo-projects/Personal_Portfolio-2.0-/venv/lib/python3.11/site-packages/django/db/utils.py", line 91, in __exit__
    raise dj_exc_value.with_traceback(traceback) from exc_value
  File "/Users/shazibsiddique/solo-projects/Personal_Portfolio-2.0-/venv/lib/python3.11/site-packages/django/db/backends/utils.py", line 105, in _execute
    return self.cursor.execute(sql, params)
           ^^^^^^^^^^^^^^^^^^^^^^^^^^^^^^^^
  File "/Users/shazibsiddique/solo-projects/Personal_Portfolio-2.0-/venv/lib/python3.11/site-packages/django/db/backends/sqlite3/base.py", line 360, in execute
    return super().execute(query, params)
           ^^^^^^^^^^^^^^^^^^^^^^^^^^^^^^
django.db.utils.OperationalError: no such column: app_sitesettings.pinterest_url
[10/Oct/2025 23:10:31] "GET / HTTP/1.1" 500 164668
[10/Oct/2025 23:10:31] "GET /favicon.ico HTTP/1.1" 302 0
Internal Server Error: /
Traceback (most recent call last):
  File "/Users/shazibsiddique/solo-projects/Personal_Portfolio-2.0-/venv/lib/python3.11/site-packages/django/db/backends/utils.py", line 105, in _execute
    return self.cursor.execute(sql, params)
           ^^^^^^^^^^^^^^^^^^^^^^^^^^^^^^^^
  File "/Users/shazibsiddique/solo-projects/Personal_Portfolio-2.0-/venv/lib/python3.11/site-packages/django/db/backends/sqlite3/base.py", line 360, in execute
    return super().execute(query, params)
           ^^^^^^^^^^^^^^^^^^^^^^^^^^^^^^
sqlite3.OperationalError: no such column: app_sitesettings.pinterest_url

The above exception was the direct cause of the following exception:

Traceback (most recent call last):
  File "/Users/shazibsiddique/solo-projects/Personal_Portfolio-2.0-/venv/lib/python3.11/site-packages/django/core/handlers/exception.py", line 55, in inner
    response = get_response(request)
               ^^^^^^^^^^^^^^^^^^^^^
  File "/Users/shazibsiddique/solo-projects/Personal_Portfolio-2.0-/venv/lib/python3.11/site-packages/django/core/handlers/base.py", line 197, in _get_response
    response = wrapped_callback(request, *callback_args, **callback_kwargs)
               ^^^^^^^^^^^^^^^^^^^^^^^^^^^^^^^^^^^^^^^^^^^^^^^^^^^^^^^^^^^^
  File "/Users/shazibsiddique/solo-projects/Personal_Portfolio-2.0-/app/views.py", line 115, in home_view
    site_settings = SiteSettings.objects.first()
                    ^^^^^^^^^^^^^^^^^^^^^^^^^^^^
  File "/Users/shazibsiddique/solo-projects/Personal_Portfolio-2.0-/venv/lib/python3.11/site-packages/django/db/models/manager.py", line 87, in manager_method
    return getattr(self.get_queryset(), name)(*args, **kwargs)
           ^^^^^^^^^^^^^^^^^^^^^^^^^^^^^^^^^^^^^^^^^^^^^^^^^^^
  File "/Users/shazibsiddique/solo-projects/Personal_Portfolio-2.0-/venv/lib/python3.11/site-packages/django/db/models/query.py", line 1104, in first
    for obj in queryset[:1]:
  File "/Users/shazibsiddique/solo-projects/Personal_Portfolio-2.0-/venv/lib/python3.11/site-packages/django/db/models/query.py", line 384, in __iter__
    self._fetch_all()
  File "/Users/shazibsiddique/solo-projects/Personal_Portfolio-2.0-/venv/lib/python3.11/site-packages/django/db/models/query.py", line 1949, in _fetch_all
    self._result_cache = list(self._iterable_class(self))
                         ^^^^^^^^^^^^^^^^^^^^^^^^^^^^^^^^
  File "/Users/shazibsiddique/solo-projects/Personal_Portfolio-2.0-/venv/lib/python3.11/site-packages/django/db/models/query.py", line 91, in __iter__
    results = compiler.execute_sql(
              ^^^^^^^^^^^^^^^^^^^^^
  File "/Users/shazibsiddique/solo-projects/Personal_Portfolio-2.0-/venv/lib/python3.11/site-packages/django/db/models/sql/compiler.py", line 1623, in execute_sql
    cursor.execute(sql, params)
  File "/Users/shazibsiddique/solo-projects/Personal_Portfolio-2.0-/venv/lib/python3.11/site-packages/django/db/backends/utils.py", line 122, in execute
    return super().execute(sql, params)
           ^^^^^^^^^^^^^^^^^^^^^^^^^^^^
  File "/Users/shazibsiddique/solo-projects/Personal_Portfolio-2.0-/venv/lib/python3.11/site-packages/django/db/backends/utils.py", line 79, in execute
    return self._execute_with_wrappers(
           ^^^^^^^^^^^^^^^^^^^^^^^^^^^^
  File "/Users/shazibsiddique/solo-projects/Personal_Portfolio-2.0-/venv/lib/python3.11/site-packages/django/db/backends/utils.py", line 92, in _execute_with_wrappers
    return executor(sql, params, many, context)
           ^^^^^^^^^^^^^^^^^^^^^^^^^^^^^^^^^^^^
  File "/Users/shazibsiddique/solo-projects/Personal_Portfolio-2.0-/venv/lib/python3.11/site-packages/django/db/backends/utils.py", line 100, in _execute
    with self.db.wrap_database_errors:
  File "/Users/shazibsiddique/solo-projects/Personal_Portfolio-2.0-/venv/lib/python3.11/site-packages/django/db/utils.py", line 91, in __exit__
    raise dj_exc_value.with_traceback(traceback) from exc_value
  File "/Users/shazibsiddique/solo-projects/Personal_Portfolio-2.0-/venv/lib/python3.11/site-packages/django/db/backends/utils.py", line 105, in _execute
    return self.cursor.execute(sql, params)
           ^^^^^^^^^^^^^^^^^^^^^^^^^^^^^^^^
  File "/Users/shazibsiddique/solo-projects/Personal_Portfolio-2.0-/venv/lib/python3.11/site-packages/django/db/backends/sqlite3/base.py", line 360, in execute
    return super().execute(query, params)
           ^^^^^^^^^^^^^^^^^^^^^^^^^^^^^^
django.db.utils.OperationalError: no such column: app_sitesettings.pinterest_url
Internal Server Error: /
Traceback (most recent call last):
  File "/Users/shazibsiddique/solo-projects/Personal_Portfolio-2.0-/venv/lib/python3.11/site-packages/django/db/backends/utils.py", line 105, in _execute
    return self.cursor.execute(sql, params)
           ^^^^^^^^^^^^^^^^^^^^^^^^^^^^^^^^
  File "/Users/shazibsiddique/solo-projects/Personal_Portfolio-2.0-/venv/lib/python3.11/site-packages/django/db/backends/sqlite3/base.py", line 360, in execute
    return super().execute(query, params)
           ^^^^^^^^^^^^^^^^^^^^^^^^^^^^^^
sqlite3.OperationalError: no such column: app_sitesettings.pinterest_url

The above exception was the direct cause of the following exception:

Traceback (most recent call last):
  File "/Users/shazibsiddique/solo-projects/Personal_Portfolio-2.0-/venv/lib/python3.11/site-packages/django/core/handlers/exception.py", line 55, in inner
    response = get_response(request)
               ^^^^^^^^^^^^^^^^^^^^^
  File "/Users/shazibsiddique/solo-projects/Personal_Portfolio-2.0-/venv/lib/python3.11/site-packages/django/core/handlers/base.py", line 197, in _get_response
    response = wrapped_callback(request, *callback_args, **callback_kwargs)
               ^^^^^^^^^^^^^^^^^^^^^^^^^^^^^^^^^^^^^^^^^^^^^^^^^^^^^^^^^^^^
  File "/Users/shazibsiddique/solo-projects/Personal_Portfolio-2.0-/app/views.py", line 115, in home_view
    site_settings = SiteSettings.objects.first()
                    ^^^^^^^^^^^^^^^^^^^^^^^^^^^^
  File "/Users/shazibsiddique/solo-projects/Personal_Portfolio-2.0-/venv/lib/python3.11/site-packages/django/db/models/manager.py", line 87, in manager_method
    return getattr(self.get_queryset(), name)(*args, **kwargs)
           ^^^^^^^^^^^^^^^^^^^^^^^^^^^^^^^^^^^^^^^^^^^^^^^^^^^
  File "/Users/shazibsiddique/solo-projects/Personal_Portfolio-2.0-/venv/lib/python3.11/site-packages/django/db/models/query.py", line 1104, in first
    for obj in queryset[:1]:
  File "/Users/shazibsiddique/solo-projects/Personal_Portfolio-2.0-/venv/lib/python3.11/site-packages/django/db/models/query.py", line 384, in __iter__
    self._fetch_all()
  File "/Users/shazibsiddique/solo-projects/Personal_Portfolio-2.0-/venv/lib/python3.11/site-packages/django/db/models/query.py", line 1949, in _fetch_all
    self._result_cache = list(self._iterable_class(self))
                         ^^^^^^^^^^^^^^^^^^^^^^^^^^^^^^^^
  File "/Users/shazibsiddique/solo-projects/Personal_Portfolio-2.0-/venv/lib/python3.11/site-packages/django/db/models/query.py", line 91, in __iter__
    results = compiler.execute_sql(
              ^^^^^^^^^^^^^^^^^^^^^
  File "/Users/shazibsiddique/solo-projects/Personal_Portfolio-2.0-/venv/lib/python3.11/site-packages/django/db/models/sql/compiler.py", line 1623, in execute_sql
    cursor.execute(sql, params)
  File "/Users/shazibsiddique/solo-projects/Personal_Portfolio-2.0-/venv/lib/python3.11/site-packages/django/db/backends/utils.py", line 122, in execute
    return super().execute(sql, params)
           ^^^^^^^^^^^^^^^^^^^^^^^^^^^^
  File "/Users/shazibsiddique/solo-projects/Personal_Portfolio-2.0-/venv/lib/python3.11/site-packages/django/db/backends/utils.py", line 79, in execute
    return self._execute_with_wrappers(
           ^^^^^^^^^^^^^^^^^^^^^^^^^^^^
  File "/Users/shazibsiddique/solo-projects/Personal_Portfolio-2.0-/venv/lib/python3.11/site-packages/django/db/backends/utils.py", line 92, in _execute_with_wrappers
    return executor(sql, params, many, context)
           ^^^^^^^^^^^^^^^^^^^^^^^^^^^^^^^^^^^^
  File "/Users/shazibsiddique/solo-projects/Personal_Portfolio-2.0-/venv/lib/python3.11/site-packages/django/db/backends/utils.py", line 100, in _execute
    with self.db.wrap_database_errors:
  File "/Users/shazibsiddique/solo-projects/Personal_Portfolio-2.0-/venv/lib/python3.11/site-packages/django/db/utils.py", line 91, in __exit__
    raise dj_exc_value.with_traceback(traceback) from exc_value
  File "/Users/shazibsiddique/solo-projects/Personal_Portfolio-2.0-/venv/lib/python3.11/site-packages/django/db/backends/utils.py", line 105, in _execute
    return self.cursor.execute(sql, params)
           ^^^^^^^^^^^^^^^^^^^^^^^^^^^^^^^^
  File "/Users/shazibsiddique/solo-projects/Personal_Portfolio-2.0-/venv/lib/python3.11/site-packages/django/db/backends/sqlite3/base.py", line 360, in execute
    return super().execute(query, params)
           ^^^^^^^^^^^^^^^^^^^^^^^^^^^^^^
django.db.utils.OperationalError: no such column: app_sitesettings.pinterest_url
[10/Oct/2025 23:10:31] "GET / HTTP/1.1" 500 164668
[10/Oct/2025 23:10:31] "GET /favicon.ico HTTP/1.1" 302 0
Internal Server Error: /
Traceback (most recent call last):
  File "/Users/shazibsiddique/solo-projects/Personal_Portfolio-2.0-/venv/lib/python3.11/site-packages/django/db/backends/utils.py", line 105, in _execute
    return self.cursor.execute(sql, params)
           ^^^^^^^^^^^^^^^^^^^^^^^^^^^^^^^^
  File "/Users/shazibsiddique/solo-projects/Personal_Portfolio-2.0-/venv/lib/python3.11/site-packages/django/db/backends/sqlite3/base.py", line 360, in execute
    return super().execute(query, params)
           ^^^^^^^^^^^^^^^^^^^^^^^^^^^^^^
sqlite3.OperationalError: no such column: app_sitesettings.pinterest_url

The above exception was the direct cause of the following exception:

Traceback (most recent call last):
  File "/Users/shazibsiddique/solo-projects/Personal_Portfolio-2.0-/venv/lib/python3.11/site-packages/django/core/handlers/exception.py", line 55, in inner
    response = get_response(request)
               ^^^^^^^^^^^^^^^^^^^^^
  File "/Users/shazibsiddique/solo-projects/Personal_Portfolio-2.0-/venv/lib/python3.11/site-packages/django/core/handlers/base.py", line 197, in _get_response
    response = wrapped_callback(request, *callback_args, **callback_kwargs)
               ^^^^^^^^^^^^^^^^^^^^^^^^^^^^^^^^^^^^^^^^^^^^^^^^^^^^^^^^^^^^
  File "/Users/shazibsiddique/solo-projects/Personal_Portfolio-2.0-/app/views.py", line 115, in home_view
    site_settings = SiteSettings.objects.first()
                    ^^^^^^^^^^^^^^^^^^^^^^^^^^^^
  File "/Users/shazibsiddique/solo-projects/Personal_Portfolio-2.0-/venv/lib/python3.11/site-packages/django/db/models/manager.py", line 87, in manager_method
    return getattr(self.get_queryset(), name)(*args, **kwargs)
           ^^^^^^^^^^^^^^^^^^^^^^^^^^^^^^^^^^^^^^^^^^^^^^^^^^^
  File "/Users/shazibsiddique/solo-projects/Personal_Portfolio-2.0-/venv/lib/python3.11/site-packages/django/db/models/query.py", line 1104, in first
    for obj in queryset[:1]:
  File "/Users/shazibsiddique/solo-projects/Personal_Portfolio-2.0-/venv/lib/python3.11/site-packages/django/db/models/query.py", line 384, in __iter__
    self._fetch_all()
  File "/Users/shazibsiddique/solo-projects/Personal_Portfolio-2.0-/venv/lib/python3.11/site-packages/django/db/models/query.py", line 1949, in _fetch_all
    self._result_cache = list(self._iterable_class(self))
                         ^^^^^^^^^^^^^^^^^^^^^^^^^^^^^^^^
  File "/Users/shazibsiddique/solo-projects/Personal_Portfolio-2.0-/venv/lib/python3.11/site-packages/django/db/models/query.py", line 91, in __iter__
    results = compiler.execute_sql(
              ^^^^^^^^^^^^^^^^^^^^^
  File "/Users/shazibsiddique/solo-projects/Personal_Portfolio-2.0-/venv/lib/python3.11/site-packages/django/db/models/sql/compiler.py", line 1623, in execute_sql
    cursor.execute(sql, params)
  File "/Users/shazibsiddique/solo-projects/Personal_Portfolio-2.0-/venv/lib/python3.11/site-packages/django/db/backends/utils.py", line 122, in execute
    return super().execute(sql, params)
           ^^^^^^^^^^^^^^^^^^^^^^^^^^^^
  File "/Users/shazibsiddique/solo-projects/Personal_Portfolio-2.0-/venv/lib/python3.11/site-packages/django/db/backends/utils.py", line 79, in execute
    return self._execute_with_wrappers(
           ^^^^^^^^^^^^^^^^^^^^^^^^^^^^
  File "/Users/shazibsiddique/solo-projects/Personal_Portfolio-2.0-/venv/lib/python3.11/site-packages/django/db/backends/utils.py", line 92, in _execute_with_wrappers
    return executor(sql, params, many, context)
           ^^^^^^^^^^^^^^^^^^^^^^^^^^^^^^^^^^^^
  File "/Users/shazibsiddique/solo-projects/Personal_Portfolio-2.0-/venv/lib/python3.11/site-packages/django/db/backends/utils.py", line 100, in _execute
    with self.db.wrap_database_errors:
  File "/Users/shazibsiddique/solo-projects/Personal_Portfolio-2.0-/venv/lib/python3.11/site-packages/django/db/utils.py", line 91, in __exit__
    raise dj_exc_value.with_traceback(traceback) from exc_value
  File "/Users/shazibsiddique/solo-projects/Personal_Portfolio-2.0-/venv/lib/python3.11/site-packages/django/db/backends/utils.py", line 105, in _execute
    return self.cursor.execute(sql, params)
           ^^^^^^^^^^^^^^^^^^^^^^^^^^^^^^^^
  File "/Users/shazibsiddique/solo-projects/Personal_Portfolio-2.0-/venv/lib/python3.11/site-packages/django/db/backends/sqlite3/base.py", line 360, in execute
    return super().execute(query, params)
           ^^^^^^^^^^^^^^^^^^^^^^^^^^^^^^
django.db.utils.OperationalError: no such column: app_sitesettings.pinterest_url
Internal Server Error: /
Traceback (most recent call last):
  File "/Users/shazibsiddique/solo-projects/Personal_Portfolio-2.0-/venv/lib/python3.11/site-packages/django/db/backends/utils.py", line 105, in _execute
    return self.cursor.execute(sql, params)
           ^^^^^^^^^^^^^^^^^^^^^^^^^^^^^^^^
  File "/Users/shazibsiddique/solo-projects/Personal_Portfolio-2.0-/venv/lib/python3.11/site-packages/django/db/backends/sqlite3/base.py", line 360, in execute
    return super().execute(query, params)
           ^^^^^^^^^^^^^^^^^^^^^^^^^^^^^^
sqlite3.OperationalError: no such column: app_sitesettings.pinterest_url

The above exception was the direct cause of the following exception:

Traceback (most recent call last):
  File "/Users/shazibsiddique/solo-projects/Personal_Portfolio-2.0-/venv/lib/python3.11/site-packages/django/core/handlers/exception.py", line 55, in inner
    response = get_response(request)
               ^^^^^^^^^^^^^^^^^^^^^
  File "/Users/shazibsiddique/solo-projects/Personal_Portfolio-2.0-/venv/lib/python3.11/site-packages/django/core/handlers/base.py", line 197, in _get_response
    response = wrapped_callback(request, *callback_args, **callback_kwargs)
               ^^^^^^^^^^^^^^^^^^^^^^^^^^^^^^^^^^^^^^^^^^^^^^^^^^^^^^^^^^^^
  File "/Users/shazibsiddique/solo-projects/Personal_Portfolio-2.0-/app/views.py", line 115, in home_view
    site_settings = SiteSettings.objects.first()
                    ^^^^^^^^^^^^^^^^^^^^^^^^^^^^
  File "/Users/shazibsiddique/solo-projects/Personal_Portfolio-2.0-/venv/lib/python3.11/site-packages/django/db/models/manager.py", line 87, in manager_method
    return getattr(self.get_queryset(), name)(*args, **kwargs)
           ^^^^^^^^^^^^^^^^^^^^^^^^^^^^^^^^^^^^^^^^^^^^^^^^^^^
  File "/Users/shazibsiddique/solo-projects/Personal_Portfolio-2.0-/venv/lib/python3.11/site-packages/django/db/models/query.py", line 1104, in first
    for obj in queryset[:1]:
  File "/Users/shazibsiddique/solo-projects/Personal_Portfolio-2.0-/venv/lib/python3.11/site-packages/django/db/models/query.py", line 384, in __iter__
    self._fetch_all()
  File "/Users/shazibsiddique/solo-projects/Personal_Portfolio-2.0-/venv/lib/python3.11/site-packages/django/db/models/query.py", line 1949, in _fetch_all
    self._result_cache = list(self._iterable_class(self))
                         ^^^^^^^^^^^^^^^^^^^^^^^^^^^^^^^^
  File "/Users/shazibsiddique/solo-projects/Personal_Portfolio-2.0-/venv/lib/python3.11/site-packages/django/db/models/query.py", line 91, in __iter__
    results = compiler.execute_sql(
              ^^^^^^^^^^^^^^^^^^^^^
  File "/Users/shazibsiddique/solo-projects/Personal_Portfolio-2.0-/venv/lib/python3.11/site-packages/django/db/models/sql/compiler.py", line 1623, in execute_sql
    cursor.execute(sql, params)
  File "/Users/shazibsiddique/solo-projects/Personal_Portfolio-2.0-/venv/lib/python3.11/site-packages/django/db/backends/utils.py", line 122, in execute
    return super().execute(sql, params)
           ^^^^^^^^^^^^^^^^^^^^^^^^^^^^
  File "/Users/shazibsiddique/solo-projects/Personal_Portfolio-2.0-/venv/lib/python3.11/site-packages/django/db/backends/utils.py", line 79, in execute
    return self._execute_with_wrappers(
           ^^^^^^^^^^^^^^^^^^^^^^^^^^^^
  File "/Users/shazibsiddique/solo-projects/Personal_Portfolio-2.0-/venv/lib/python3.11/site-packages/django/db/backends/utils.py", line 92, in _execute_with_wrappers
    return executor(sql, params, many, context)
           ^^^^^^^^^^^^^^^^^^^^^^^^^^^^^^^^^^^^
  File "/Users/shazibsiddique/solo-projects/Personal_Portfolio-2.0-/venv/lib/python3.11/site-packages/django/db/backends/utils.py", line 100, in _execute
    with self.db.wrap_database_errors:
  File "/Users/shazibsiddique/solo-projects/Personal_Portfolio-2.0-/venv/lib/python3.11/site-packages/django/db/utils.py", line 91, in __exit__
    raise dj_exc_value.with_traceback(traceback) from exc_value
  File "/Users/shazibsiddique/solo-projects/Personal_Portfolio-2.0-/venv/lib/python3.11/site-packages/django/db/backends/utils.py", line 105, in _execute
    return self.cursor.execute(sql, params)
           ^^^^^^^^^^^^^^^^^^^^^^^^^^^^^^^^
  File "/Users/shazibsiddique/solo-projects/Personal_Portfolio-2.0-/venv/lib/python3.11/site-packages/django/db/backends/sqlite3/base.py", line 360, in execute
    return super().execute(query, params)
           ^^^^^^^^^^^^^^^^^^^^^^^^^^^^^^
django.db.utils.OperationalError: no such column: app_sitesettings.pinterest_url
[10/Oct/2025 23:10:31] "GET / HTTP/1.1" 500 164668
[10/Oct/2025 23:10:31] "GET /favicon.ico HTTP/1.1" 302 0
